Workbook

Sheet Welcome
B6: Buy or Rent model V8 David Bartoš
B17: last updated May 2026
B19: Buy-versus-Rent Decision Support Model. Excel financial model developed for the Master's thesis Buy or Rent? Development of a Decision Support Tool for Czech Households (VŠE Prague, David Bartos, May 2026). Calibrated to Prague apartment market conditions as of Q1 2026 . Web version at https://vse-buyorrent.github.io/decision-tool/. Maintenance documented in Annex 1 of the thesis.
C20: The excel includes:
C21: Input sheet: | D21: This is where all the relevant user facing variables are. Changing them influences the result and contorls the model. The sheet also includes basic graphs showing the progression of networth
C22: Calculations: | D22: Here the main claculations are located and the logic of the model can be understood based on the formulas here
C23: Results: | D23: Include the sensitivity decomposition (hardcoded from decompositon sheet E42 outputs), decomposition of the cashflows; initial result sheet that is used for the outputs and graphs.;annual cost matrix logic is used for the costdecompositon in years
C24: Data: | D24: Price data from Sreality; rent price from sreality and toplak;flat price from CSU; Damodaran SP500 data

Sheet Input sheet(dashboard)
B1: Input assumption | C1: Unit
B2: Buying | E2: (monthly reculculation if applicable)
B3: Flatprice | C3: czk | D3: 8868530
B4: LTV | C4: % | D4: 0.9
B5: Interest(annual) | C5: % | D5: 0.0446 | E5: =((1+D5)^(1/12))-1 -> 0.0036427886
B6: Time to maturity | C6: years | D6: 30
B7: Mortgage Insurance (% of mortgage payment) | C7: % | D7: 0.08 | E7: =((1+D7)^(1/12))-1 -> 0.0064340301
B8: Repairs(annual % of property value) | C8: % | D8: 0.0125 | E8: =((1+D8)^(1/12))-1 -> 0.001035746
B9: Other fees(house admin, repair fund, monthly) | C9: czk | D9: 3000
B10: Purchase costs | C10: % | D10: 0.01
B11: Selling costs | C11: % | D11: 0.01
B12: Relestate tax (annual) | C12: czk | D12: =D30*D31*D32*D33*D34 -> 2310
B13: Interest Tax deduction limit | C13: czk | D13: 150000
B14: DSTI | C14: % | D14: 0.45
B15: Property insurance (annual) | C15: czk | D15: 4000 | E15: =D15/12 -> 333.33333
B16: Renting
B17: Monthly rent | C17: czk | D17: 25905
B18: Deposit | C18: months of rent | D18: 2
B19: Moving(how often) | C19: years | D19: =52/12 -> 4.3333333
B20: Moving cost | C20: czk | D20: 8000
B21: Macro
B22: Inflation | C22: % | D22: 0.025 | E22: =((1+D22)^(1/12))-1 -> 0.0020598363
B23: Rent growth | C23: % | D23: 0.05 | E23: =((1+D23)^(1/12))-1 -> 0.0040741238
B24: Real estate price growth | C24: % | D24: 0.05 | E24: =((1+D24)^(1/12))-1 -> 0.0040741238
B25: Investment growth | C25: % | D25: 0.08 | E25: =((1+D25)^(1/12))-1 -> 0.0064340301
B26: Further assumptions
B27: Time horizont | C27: years | D27: 40
B28: tax rate | C28: % | D28: 0.15
B29: Real estate tax
B30: Area adjustment | C30: # | D30: 1.2
B31: Cost | C31: # | D31: 3.5
B32: Base coefieicent | C32: # | D32: 5
B33: Local coeficient | C33: # | D33: 2
B34: Flat area | C34: sqm | D34: 55
G35: Outputs | H35: Buy | I35: Rent | J35: Difference | K35: Winner | L35: Buy liquidity | M35: Buy liqudity in % | N35: Net worth Crossover year | O35: Annual costs Crossover year | P35: Monthly mortgage payment | Q35: Required net income(based on DSTI)
G36: Terminal netwroth | H36: =INDEX(Calculations!W:W,MATCH(D27*12,Calculations!B:B,0),1) -> 79496192 | I36: =INDEX(Calculations!AH:AH,MATCH(D27*12,Calculations!B:B,0),1) -> 74271374 | J36: =ABS(H36-I36) -> 5224817.6 | K36: =IF(H36>I36,"BUY","RENT") -> BUY | L36: =INDEX(Calculations!V:V,MATCH(D27*12,Calculations!B:B,0),1) -> 17686184 | M36: =L36/H36 -> 0.22247838 | N36: =IF(IFERROR(MIN(Results!$K$5:$K$64),"-")>D27,"",IFERROR(MIN(Results!$K$5:$K$64),"-")) | O36: =IF(IFERROR(MIN(Results!$L$5:$L$64),"-")>D27,"",IFERROR(MIN(Results!$L$5:$L$64),"-")) -> 22 | P36: =Calculations!$E$4 -> 39834.138 | Q36: =$P$36/$D$14 -> 88520.306
G37: Annual costs in year
G38: 1 | H38: =INDEX(Results!$G:$H,MATCH('Input sheet(dashboard)'!$G38,Results!$D:$D,0),1) -> 738474.94 | I38: =INDEX(Results!$G:$H,MATCH('Input sheet(dashboard)'!$G38,Results!$D:$D,0),2) -> 369731.12
G39: 10 | H39: =INDEX(Results!$G:$H,MATCH('Input sheet(dashboard)'!$G39,Results!$D:$D,0),1) -> 722283.06 | I39: =INDEX(Results!$G:$H,MATCH('Input sheet(dashboard)'!$G39,Results!$D:$D,0),2) -> 493200.01
G40: 20 | H40: =INDEX(Results!$G:$H,MATCH('Input sheet(dashboard)'!$G40,Results!$D:$D,0),1) -> 846893.55 | I40: =INDEX(Results!$G:$H,MATCH('Input sheet(dashboard)'!$G40,Results!$D:$D,0),2) -> 803370.84
...

Sheet Calculations>>>

Sheet Calculations
E1: Mortgage | X1: Renting | AI1: Output
B2: period | C2: year | D2: Month | E2: Mortgage payment | F2: Mortgage interest | G2: Mortgage insurance | H2: Mortgage principal | I2: Mortgage debt | J2: Property value | K2: house repairs | L2: OR/ flat fees/other fees | M2: purchase cost | N2: selling cost | O2: Interest Tax benefit COST | P2: Interest Tax benefit CF | Q2: Realestate tax | R2: property insurance | S2: Costs before investing | T2: annual costs before investing | U2: New investment | V2: Investment hodling | W2: NETWORTH | X2: Rent | Y2: Insurance | AB2: Deposit CF | AC2: moving cost | AD2: costs before investing | AE2: annual costs before investing | AF2: Saving vs Mo. | AG2: new investment | AH2: NETWORTH(invest.) | AI2: Totalvalue | AJ2: Annual costs | AK2: Annual CF | AL2: Cumulative CF
B3: 0 | C3: 1 | D3: 0 | I3: ='Input sheet(dashboard)'!D3*'Input sheet(dashboard)'!D4 -> 7981677 | J3: =IF(B3<='Input sheet(dashboard)'!$D$27*12,'Input sheet(dashboard)'!$D$3*(1+'Input sheet(dashboard)'!$E$24)^B3,0) -> 8868530 | V3: 0 | W3: =IF(B3<='Input sheet(dashboard)'!$D$27*12,J3-I3+V3-N3,0) -> 886853 | AH3: =IF(B3<='Input sheet(dashboard)'!$D$27*12,'Input sheet(dashboard)'!$D$3*(1-'Input sheet(dashboard)'!$D$4)," ") -> 886853
B4: =B3+1 -> 1 | C4: 1 | D4: 1 | E4: =IF(C4<='Input sheet(dashboard)'!$D$6, -PMT('Input sheet(dashboard)'!$E$5,'Input sheet(dashboard)'!$D$6*12,'Input sheet(dashboard)'!$D$3*'Input sheet(dashboard)'!$D$4),0) -> 39834.138 | F4: =I3*'Input sheet(dashboard)'!$E$5 -> 29075.562 | G4: =IF(C4<='Input sheet(dashboard)'!$D$6,E4*'Input sheet(dashboard)'!$D$7,0) -> 3186.731 | H4: =E4-F4 -> 10758.576 | I4: =I3-H4 -> 7970918.4 | J4: =IF(B4<='Input sheet(dashboard)'!$D$27*12,'Input sheet(dashboard)'!$D$3*(1+'Input sheet(dashboard)'!$E$24)^B4,0) -> 8904661.5 | K4: =IF(B4<='Input sheet(dashboard)'!$D$27*12,J4*'Input sheet(dashboard)'!$E$8,0) -> 9222.9676 | L4: =IF(B4<='Input sheet(dashboard)'!$D$27*12,'Input sheet(dashboard)'!$D$9*(1+'Input sheet(dashboard)'!$E$22)^B4,0) -> 3006.1795 | M4: =IF(B4=1,'Input sheet(dashboard)'!$D$3*'Input sheet(dashboard)'!$D$10,0) -> 88685.3 | N4: =IF(B4='Input sheet(dashboard)'!$D$27*12,J4*'Input sheet(dashboard)'!$D$11,0) -> 0 | O4: =IF(SUM(F4:F15)>=150000,150000/12*'Input sheet(dashboard)'!$D$28,SUM(F4:F15)/12*'Input sheet(dashboard)'!$D$28) -> 1875 | Q4: =IF(B4<='Input sheet(dashboard)'!$D$27*12,'Input sheet(dashboard)'!$D$12/12,0) -> 192.5 | R4: =IF(B4<='Input sheet(dashboard)'!$D$27*12,('Input sheet(dashboard)'!$D$15/12)*(1+'Input sheet(dashboard)'!$E$22)^Calculations!B4,0) -> 334.01995 | S4: =IF(B4<='Input sheet(dashboard)'!$D$27*12,(E4+G4+K4+L4-O4+M4+Q4+R4),0) -> 142586.84 | U4: =IF(B4<='Input sheet(dashboard)'!$D$27*12,IF(S4<AD4,AD4-S4,0),0) -> 0 | V4: =IF(B4<='Input sheet(dashboard)'!$D$27*12,V3*(1+'Input sheet(dashboard)'!$E$25)+U4,0) -> 0 | W4: =IF(B4<='Input sheet(dashboard)'!$D$27*12,J4-I4+V4-N4,0) -> 933743.06 | X4: =IF(B4<='Input sheet(dashboard)'!$D$27*12,'Input sheet(dashboard)'!$D$17*(1+'Input sheet(dashboard)'!$E$23)^(B4-1),0) -> 25905 | AB4: =IF(B4=1,'Input sheet(dashboard)'!$D$18*Calculations!X4,IF(Calculations!B4=12*'Input sheet(dashboard)'!$D$27,'Input sheet(dashboard)'!$D$18*-Calculations!X4,0)) -> 51810 | AD4: =X4+Y4+AB4+AC4 -> 77715 | AF4: =S4-AD4 -> 64871.836 | AG4: =IF(AF4>0,AF4,0) -> 64871.836 | AH4: =IF(B4<='Input sheet(dashboard)'!$D$27*12,AH3*(1+'Input sheet(dashboard)'!$E$25)+AG4," ") -> 957430.87
B5: =B4+1 -> 2 | C5: 1 | D5: 2 | E5: =IF(C5<='Input sheet(dashboard)'!$D$6, -PMT('Input sheet(dashboard)'!$E$5,'Input sheet(dashboard)'!$D$6*12,'Input sheet(dashboard)'!$D$3*'Input sheet(dashboard)'!$D$4),0) -> 39834.138 | F5: =I4*'Input sheet(dashboard)'!$E$5 -> 29036.371 | G5: =IF(C5<='Input sheet(dashboard)'!$D$6,E5*'Input sheet(dashboard)'!$D$7,0) -> 3186.731 | H5: =E5-F5 -> 10797.767 | I5: =I4-H5 -> 7960120.7 | J5: =IF(B5<='Input sheet(dashboard)'!$D$27*12,'Input sheet(dashboard)'!$D$3*(1+'Input sheet(dashboard)'!$E$24)^B5,0) -> 8940940.2 | K5: =IF(B5<='Input sheet(dashboard)'!$D$27*12,J5*'Input sheet(dashboard)'!$E$8,0) -> 9260.5432 | L5: =IF(B5<='Input sheet(dashboard)'!$D$27*12,'Input sheet(dashboard)'!$D$9*(1+'Input sheet(dashboard)'!$E$22)^B5,0) -> 3012.3717 | M5: =IF(B5=1,'Input sheet(dashboard)'!$D$3*'Input sheet(dashboard)'!$D$10,0) -> 0 | N5: =IF(B5='Input sheet(dashboard)'!$D$27*12,J5*'Input sheet(dashboard)'!$D$11,0) -> 0 | O5: =IF(SUM(F5:F16)>=150000,150000/12*'Input sheet(dashboard)'!$D$28,SUM(F5:F16)/12*'Input sheet(dashboard)'!$D$28) -> 1875 | Q5: =IF(B5<='Input sheet(dashboard)'!$D$27*12,'Input sheet(dashboard)'!$D$12/12,0) -> 192.5 | R5: =IF(B5<='Input sheet(dashboard)'!$D$27*12,('Input sheet(dashboard)'!$D$15/12)*(1+'Input sheet(dashboard)'!$E$22)^Calculations!B5,0) -> 334.70797 | S5: =IF(B5<='Input sheet(dashboard)'!$D$27*12,(E5+G5+K5+L5-O5+M5+Q5+R5),0) -> 53945.992 | U5: =IF(B5<='Input sheet(dashboard)'!$D$27*12,IF(S5<AD5,AD5-S5,0),0) -> 0 | V5: =IF(B5<='Input sheet(dashboard)'!$D$27*12,V4*(1+'Input sheet(dashboard)'!$E$25)+U5,0) -> 0 | W5: =IF(B5<='Input sheet(dashboard)'!$D$27*12,J5-I5+V5-N5,0) -> 980819.52 | X5: =IF(B5<='Input sheet(dashboard)'!$D$27*12,'Input sheet(dashboard)'!$D$17*(1+'Input sheet(dashboard)'!$E$23)^(B5-1),0) -> 26010.54 | AB5: =IF(B5=1,'Input sheet(dashboard)'!$D$18*Calculations!X5,IF(Calculations!B5=12*'Input sheet(dashboard)'!$D$27,'Input sheet(dashboard)'!$D$18*-Calculations!X5,0)) -> 0 | AC5: =IF(B5<='Input sheet(dashboard)'!$D$27*12,IF(MOD(B4,'Input sheet(dashboard)'!$D$19*12),0,'Input sheet(dashboard)'!$D$20*(1+'Input sheet(dashboard)'!$E$22)^Calculations!B5),0) -> 0 | AD5: =X5+Y5+AB5+AC5 -> 26010.54 | AF5: =S5-AD5 -> 27935.452 | AG5: =IF(AF5>0,AF5,0) -> 27935.452 | AH5: =IF(B5<='Input sheet(dashboard)'!$D$27*12,AH4*(1+'Input sheet(dashboard)'!$E$25)+AG5," ") -> 991526.47
B6: =B5+1 -> 3 | C6: 1 | D6: 3 | E6: =IF(C6<='Input sheet(dashboard)'!$D$6, -PMT('Input sheet(dashboard)'!$E$5,'Input sheet(dashboard)'!$D$6*12,'Input sheet(dashboard)'!$D$3*'Input sheet(dashboard)'!$D$4),0) -> 39834.138 | F6: =I5*'Input sheet(dashboard)'!$E$5 -> 28997.037 | G6: =IF(C6<='Input sheet(dashboard)'!$D$6,E6*'Input sheet(dashboard)'!$D$7,0) -> 3186.731 | H6: =E6-F6 -> 10837.101 | I6: =I5-H6 -> 7949283.6 | J6: =IF(B6<='Input sheet(dashboard)'!$D$27*12,'Input sheet(dashboard)'!$D$3*(1+'Input sheet(dashboard)'!$E$24)^B6,0) -> 8977366.7 | K6: =IF(B6<='Input sheet(dashboard)'!$D$27*12,J6*'Input sheet(dashboard)'!$E$8,0) -> 9298.2718 | L6: =IF(B6<='Input sheet(dashboard)'!$D$27*12,'Input sheet(dashboard)'!$D$9*(1+'Input sheet(dashboard)'!$E$22)^B6,0) -> 3018.5767 | M6: =IF(B6=1,'Input sheet(dashboard)'!$D$3*'Input sheet(dashboard)'!$D$10,0) -> 0 | N6: =IF(B6='Input sheet(dashboard)'!$D$27*12,J6*'Input sheet(dashboard)'!$D$11,0) -> 0 | O6: =IF(SUM(F6:F17)>=150000,150000/12*'Input sheet(dashboard)'!$D$28,SUM(F6:F17)/12*'Input sheet(dashboard)'!$D$28) -> 1875 | Q6: =IF(B6<='Input sheet(dashboard)'!$D$27*12,'Input sheet(dashboard)'!$D$12/12,0) -> 192.5 | R6: =IF(B6<='Input sheet(dashboard)'!$D$27*12,('Input sheet(dashboard)'!$D$15/12)*(1+'Input sheet(dashboard)'!$E$22)^Calculations!B6,0) -> 335.39742 | S6: =IF(B6<='Input sheet(dashboard)'!$D$27*12,(E6+G6+K6+L6-O6+M6+Q6+R6),0) -> 53990.615 | U6: =IF(B6<='Input sheet(dashboard)'!$D$27*12,IF(S6<AD6,AD6-S6,0),0) -> 0 | V6: =IF(B6<='Input sheet(dashboard)'!$D$27*12,V5*(1+'Input sheet(dashboard)'!$E$25)+U6,0) -> 0 | W6: =IF(B6<='Input sheet(dashboard)'!$D$27*12,J6-I6+V6-N6,0) -> 1028083.1 | X6: =IF(B6<='Input sheet(dashboard)'!$D$27*12,'Input sheet(dashboard)'!$D$17*(1+'Input sheet(dashboard)'!$E$23)^(B6-1),0) -> 26116.51 | AB6: =IF(B6=1,'Input sheet(dashboard)'!$D$18*Calculations!X6,IF(Calculations!B6=12*'Input sheet(dashboard)'!$D$27,'Input sheet(dashboard)'!$D$18*-Calculations!X6,0)) -> 0 | AC6: =IF(B6<='Input sheet(dashboard)'!$D$27*12,IF(MOD(B5,'Input sheet(dashboard)'!$D$19*12),0,'Input sheet(dashboard)'!$D$20*(1+'Input sheet(dashboard)'!$E$22)^Calculations!B6),0) -> 0 | AD6: =X6+Y6+AB6+AC6 -> 26116.51 | AF6: =S6-AD6 -> 27874.105 | AG6: =IF(AF6>0,AF6,0) -> 27874.105 | AH6: =IF(B6<='Input sheet(dashboard)'!$D$27*12,AH5*(1+'Input sheet(dashboard)'!$E$25)+AG6," ") -> 1025780.1
B7: =B6+1 -> 4 | C7: 1 | D7: 4 | E7: =IF(C7<='Input sheet(dashboard)'!$D$6, -PMT('Input sheet(dashboard)'!$E$5,'Input sheet(dashboard)'!$D$6*12,'Input sheet(dashboard)'!$D$3*'Input sheet(dashboard)'!$D$4),0) -> 39834.138 | F7: =I6*'Input sheet(dashboard)'!$E$5 -> 28957.56 | G7: =IF(C7<='Input sheet(dashboard)'!$D$6,E7*'Input sheet(dashboard)'!$D$7,0) -> 3186.731 | H7: =E7-F7 -> 10876.578 | I7: =I6-H7 -> 7938407 | J7: =IF(B7<='Input sheet(dashboard)'!$D$27*12,'Input sheet(dashboard)'!$D$3*(1+'Input sheet(dashboard)'!$E$24)^B7,0) -> 9013941.6 | K7: =IF(B7<='Input sheet(dashboard)'!$D$27*12,J7*'Input sheet(dashboard)'!$E$8,0) -> 9336.1541 | L7: =IF(B7<='Input sheet(dashboard)'!$D$27*12,'Input sheet(dashboard)'!$D$9*(1+'Input sheet(dashboard)'!$E$22)^B7,0) -> 3024.7945 | M7: =IF(B7=1,'Input sheet(dashboard)'!$D$3*'Input sheet(dashboard)'!$D$10,0) -> 0 | N7: =IF(B7='Input sheet(dashboard)'!$D$27*12,J7*'Input sheet(dashboard)'!$D$11,0) -> 0 | O7: =IF(SUM(F7:F18)>=150000,150000/12*'Input sheet(dashboard)'!$D$28,SUM(F7:F18)/12*'Input sheet(dashboard)'!$D$28) -> 1875 | Q7: =IF(B7<='Input sheet(dashboard)'!$D$27*12,'Input sheet(dashboard)'!$D$12/12,0) -> 192.5 | R7: =IF(B7<='Input sheet(dashboard)'!$D$27*12,('Input sheet(dashboard)'!$D$15/12)*(1+'Input sheet(dashboard)'!$E$22)^Calculations!B7,0) -> 336.08828 | S7: =IF(B7<='Input sheet(dashboard)'!$D$27*12,(E7+G7+K7+L7-O7+M7+Q7+R7),0) -> 54035.406 | U7: =IF(B7<='Input sheet(dashboard)'!$D$27*12,IF(S7<AD7,AD7-S7,0),0) -> 0 | V7: =IF(B7<='Input sheet(dashboard)'!$D$27*12,V6*(1+'Input sheet(dashboard)'!$E$25)+U7,0) -> 0 | W7: =IF(B7<='Input sheet(dashboard)'!$D$27*12,J7-I7+V7-N7,0) -> 1075534.6 | X7: =IF(B7<='Input sheet(dashboard)'!$D$27*12,'Input sheet(dashboard)'!$D$17*(1+'Input sheet(dashboard)'!$E$23)^(B7-1),0) -> 26222.912 | AB7: =IF(B7=1,'Input sheet(dashboard)'!$D$18*Calculations!X7,IF(Calculations!B7=12*'Input sheet(dashboard)'!$D$27,'Input sheet(dashboard)'!$D$18*-Calculations!X7,0)) -> 0 | AC7: =IF(B7<='Input sheet(dashboard)'!$D$27*12,IF(MOD(B6,'Input sheet(dashboard)'!$D$19*12),0,'Input sheet(dashboard)'!$D$20*(1+'Input sheet(dashboard)'!$E$22)^Calculations!B7),0) -> 0 | AD7: =X7+Y7+AB7+AC7 -> 26222.912 | AF7: =S7-AD7 -> 27812.494 | AG7: =IF(AF7>0,AF7,0) -> 27812.494 | AH7: =IF(B7<='Input sheet(dashboard)'!$D$27*12,AH6*(1+'Input sheet(dashboard)'!$E$25)+AG7," ") -> 1060192.5
B8: =B7+1 -> 5 | C8: 1 | D8: 5 | E8: =IF(C8<='Input sheet(dashboard)'!$D$6, -PMT('Input sheet(dashboard)'!$E$5,'Input sheet(dashboard)'!$D$6*12,'Input sheet(dashboard)'!$D$3*'Input sheet(dashboard)'!$D$4),0) -> 39834.138 | F8: =I7*'Input sheet(dashboard)'!$E$5 -> 28917.939 | G8: =IF(C8<='Input sheet(dashboard)'!$D$6,E8*'Input sheet(dashboard)'!$D$7,0) -> 3186.731 | H8: =E8-F8 -> 10916.199 | I8: =I7-H8 -> 7927490.8 | J8: =IF(B8<='Input sheet(dashboard)'!$D$27*12,'Input sheet(dashboard)'!$D$3*(1+'Input sheet(dashboard)'!$E$24)^B8,0) -> 9050665.5 | K8: =IF(B8<='Input sheet(dashboard)'!$D$27*12,J8*'Input sheet(dashboard)'!$E$8,0) -> 9374.1907 | L8: =IF(B8<='Input sheet(dashboard)'!$D$27*12,'Input sheet(dashboard)'!$D$9*(1+'Input sheet(dashboard)'!$E$22)^B8,0) -> 3031.0251 | M8: =IF(B8=1,'Input sheet(dashboard)'!$D$3*'Input sheet(dashboard)'!$D$10,0) -> 0 | N8: =IF(B8='Input sheet(dashboard)'!$D$27*12,J8*'Input sheet(dashboard)'!$D$11,0) -> 0 | O8: =IF(SUM(F8:F19)>=150000,150000/12*'Input sheet(dashboard)'!$D$28,SUM(F8:F19)/12*'Input sheet(dashboard)'!$D$28) -> 1875 | Q8: =IF(B8<='Input sheet(dashboard)'!$D$27*12,'Input sheet(dashboard)'!$D$12/12,0) -> 192.5 | R8: =IF(B8<='Input sheet(dashboard)'!$D$27*12,('Input sheet(dashboard)'!$D$15/12)*(1+'Input sheet(dashboard)'!$E$22)^Calculations!B8,0) -> 336.78057 | S8: =IF(B8<='Input sheet(dashboard)'!$D$27*12,(E8+G8+K8+L8-O8+M8+Q8+R8),0) -> 54080.365 | U8: =IF(B8<='Input sheet(dashboard)'!$D$27*12,IF(S8<AD8,AD8-S8,0),0) -> 0 | V8: =IF(B8<='Input sheet(dashboard)'!$D$27*12,V7*(1+'Input sheet(dashboard)'!$E$25)+U8,0) -> 0 | W8: =IF(B8<='Input sheet(dashboard)'!$D$27*12,J8-I8+V8-N8,0) -> 1123174.7 | X8: =IF(B8<='Input sheet(dashboard)'!$D$27*12,'Input sheet(dashboard)'!$D$17*(1+'Input sheet(dashboard)'!$E$23)^(B8-1),0) -> 26329.748 | AB8: =IF(B8=1,'Input sheet(dashboard)'!$D$18*Calculations!X8,IF(Calculations!B8=12*'Input sheet(dashboard)'!$D$27,'Input sheet(dashboard)'!$D$18*-Calculations!X8,0)) -> 0 | AC8: =IF(B8<='Input sheet(dashboard)'!$D$27*12,IF(MOD(B7,'Input sheet(dashboard)'!$D$19*12),0,'Input sheet(dashboard)'!$D$20*(1+'Input sheet(dashboard)'!$E$22)^Calculations!B8),0) -> 0 | AD8: =X8+Y8+AB8+AC8 -> 26329.748 | AF8: =S8-AD8 -> 27750.618 | AG8: =IF(AF8>0,AF8,0) -> 27750.618 | AH8: =IF(B8<='Input sheet(dashboard)'!$D$27*12,AH7*(1+'Input sheet(dashboard)'!$E$25)+AG8," ") -> 1094764.4
B9: =B8+1 -> 6 | C9: 1 | D9: 6 | E9: =IF(C9<='Input sheet(dashboard)'!$D$6, -PMT('Input sheet(dashboard)'!$E$5,'Input sheet(dashboard)'!$D$6*12,'Input sheet(dashboard)'!$D$3*'Input sheet(dashboard)'!$D$4),0) -> 39834.138 | F9: =I8*'Input sheet(dashboard)'!$E$5 -> 28878.173 | G9: =IF(C9<='Input sheet(dashboard)'!$D$6,E9*'Input sheet(dashboard)'!$D$7,0) -> 3186.731 | H9: =E9-F9 -> 10955.965 | I9: =I8-H9 -> 7916534.8 | J9: =IF(B9<='Input sheet(dashboard)'!$D$27*12,'Input sheet(dashboard)'!$D$3*(1+'Input sheet(dashboard)'!$E$24)^B9,0) -> 9087539 | K9: =IF(B9<='Input sheet(dashboard)'!$D$27*12,J9*'Input sheet(dashboard)'!$E$8,0) -> 9412.3823 | L9: =IF(B9<='Input sheet(dashboard)'!$D$27*12,'Input sheet(dashboard)'!$D$9*(1+'Input sheet(dashboard)'!$E$22)^B9,0) -> 3037.2685 | M9: =IF(B9=1,'Input sheet(dashboard)'!$D$3*'Input sheet(dashboard)'!$D$10,0) -> 0 | N9: =IF(B9='Input sheet(dashboard)'!$D$27*12,J9*'Input sheet(dashboard)'!$D$11,0) -> 0 | O9: =IF(SUM(F9:F20)>=150000,150000/12*'Input sheet(dashboard)'!$D$28,SUM(F9:F20)/12*'Input sheet(dashboard)'!$D$28) -> 1875 | Q9: =IF(B9<='Input sheet(dashboard)'!$D$27*12,'Input sheet(dashboard)'!$D$12/12,0) -> 192.5 | R9: =IF(B9<='Input sheet(dashboard)'!$D$27*12,('Input sheet(dashboard)'!$D$15/12)*(1+'Input sheet(dashboard)'!$E$22)^Calculations!B9,0) -> 337.47428 | S9: =IF(B9<='Input sheet(dashboard)'!$D$27*12,(E9+G9+K9+L9-O9+M9+Q9+R9),0) -> 54125.494 | U9: =IF(B9<='Input sheet(dashboard)'!$D$27*12,IF(S9<AD9,AD9-S9,0),0) -> 0 | V9: =IF(B9<='Input sheet(dashboard)'!$D$27*12,V8*(1+'Input sheet(dashboard)'!$E$25)+U9,0) -> 0 | W9: =IF(B9<='Input sheet(dashboard)'!$D$27*12,J9-I9+V9-N9,0) -> 1171004.2 | X9: =IF(B9<='Input sheet(dashboard)'!$D$27*12,'Input sheet(dashboard)'!$D$17*(1+'Input sheet(dashboard)'!$E$23)^(B9-1),0) -> 26437.018 | AB9: =IF(B9=1,'Input sheet(dashboard)'!$D$18*Calculations!X9,IF(Calculations!B9=12*'Input sheet(dashboard)'!$D$27,'Input sheet(dashboard)'!$D$18*-Calculations!X9,0)) -> 0 | AC9: =IF(B9<='Input sheet(dashboard)'!$D$27*12,IF(MOD(B8,'Input sheet(dashboard)'!$D$19*12),0,'Input sheet(dashboard)'!$D$20*(1+'Input sheet(dashboard)'!$E$22)^Calculations!B9),0) -> 0 | AD9: =X9+Y9+AB9+AC9 -> 26437.018 | AF9: =S9-AD9 -> 27688.476 | AG9: =IF(AF9>0,AF9,0) -> 27688.476 | AH9: =IF(B9<='Input sheet(dashboard)'!$D$27*12,AH8*(1+'Input sheet(dashboard)'!$E$25)+AG9," ") -> 1129496.6
B10: =B9+1 -> 7 | C10: 1 | D10: 7 | E10: =IF(C10<='Input sheet(dashboard)'!$D$6, -PMT('Input sheet(dashboard)'!$E$5,'Input sheet(dashboard)'!$D$6*12,'Input sheet(dashboard)'!$D$3*'Input sheet(dashboard)'!$D$4),0) -> 39834.138 | F10: =I9*'Input sheet(dashboard)'!$E$5 -> 28838.263 | G10: =IF(C10<='Input sheet(dashboard)'!$D$6,E10*'Input sheet(dashboard)'!$D$7,0) -> 3186.731 | H10: =E10-F10 -> 10995.875 | I10: =I9-H10 -> 7905538.9 | J10: =IF(B10<='Input sheet(dashboard)'!$D$27*12,'Input sheet(dashboard)'!$D$3*(1+'Input sheet(dashboard)'!$E$24)^B10,0) -> 9124562.8 | K10: =IF(B10<='Input sheet(dashboard)'!$D$27*12,J10*'Input sheet(dashboard)'!$E$8,0) -> 9450.7295 | L10: =IF(B10<='Input sheet(dashboard)'!$D$27*12,'Input sheet(dashboard)'!$D$9*(1+'Input sheet(dashboard)'!$E$22)^B10,0) -> 3043.5248 | M10: =IF(B10=1,'Input sheet(dashboard)'!$D$3*'Input sheet(dashboard)'!$D$10,0) -> 0 | N10: =IF(B10='Input sheet(dashboard)'!$D$27*12,J10*'Input sheet(dashboard)'!$D$11,0) -> 0 | O10: =IF(SUM(F10:F21)>=150000,150000/12*'Input sheet(dashboard)'!$D$28,SUM(F10:F21)/12*'Input sheet(dashboard)'!$D$28) -> 1875 | Q10: =IF(B10<='Input sheet(dashboard)'!$D$27*12,'Input sheet(dashboard)'!$D$12/12,0) -> 192.5 | R10: =IF(B10<='Input sheet(dashboard)'!$D$27*12,('Input sheet(dashboard)'!$D$15/12)*(1+'Input sheet(dashboard)'!$E$22)^Calculations!B10,0) -> 338.16942 | S10: =IF(B10<='Input sheet(dashboard)'!$D$27*12,(E10+G10+K10+L10-O10+M10+Q10+R10),0) -> 54170.793 | U10: =IF(B10<='Input sheet(dashboard)'!$D$27*12,IF(S10<AD10,AD10-S10,0),0) -> 0 | V10: =IF(B10<='Input sheet(dashboard)'!$D$27*12,V9*(1+'Input sheet(dashboard)'!$E$25)+U10,0) -> 0 | W10: =IF(B10<='Input sheet(dashboard)'!$D$27*12,J10-I10+V10-N10,0) -> 1219023.8 | X10: =IF(B10<='Input sheet(dashboard)'!$D$27*12,'Input sheet(dashboard)'!$D$17*(1+'Input sheet(dashboard)'!$E$23)^(B10-1),0) -> 26544.726 | AB10: =IF(B10=1,'Input sheet(dashboard)'!$D$18*Calculations!X10,IF(Calculations!B10=12*'Input sheet(dashboard)'!$D$27,'Input sheet(dashboard)'!$D$18*-Calculations!X10,0)) -> 0 | AC10: =IF(B10<='Input sheet(dashboard)'!$D$27*12,IF(MOD(B9,'Input sheet(dashboard)'!$D$19*12),0,'Input sheet(dashboard)'!$D$20*(1+'Input sheet(dashboard)'!$E$22)^Calculations!B10),0) -> 0 | AD10: =X10+Y10+AB10+AC10 -> 26544.726 | AF10: =S10-AD10 -> 27626.067 | AG10: =IF(AF10>0,AF10,0) -> 27626.067 | AH10: =IF(B10<='Input sheet(dashboard)'!$D$27*12,AH9*(1+'Input sheet(dashboard)'!$E$25)+AG10," ") -> 1164389.9
B11: =B10+1 -> 8 | C11: 1 | D11: 8 | E11: =IF(C11<='Input sheet(dashboard)'!$D$6, -PMT('Input sheet(dashboard)'!$E$5,'Input sheet(dashboard)'!$D$6*12,'Input sheet(dashboard)'!$D$3*'Input sheet(dashboard)'!$D$4),0) -> 39834.138 | F11: =I10*'Input sheet(dashboard)'!$E$5 -> 28798.207 | G11: =IF(C11<='Input sheet(dashboard)'!$D$6,E11*'Input sheet(dashboard)'!$D$7,0) -> 3186.731 | H11: =E11-F11 -> 11035.931 | I11: =I10-H11 -> 7894503 | J11: =IF(B11<='Input sheet(dashboard)'!$D$27*12,'Input sheet(dashboard)'!$D$3*(1+'Input sheet(dashboard)'!$E$24)^B11,0) -> 9161737.4 | K11: =IF(B11<='Input sheet(dashboard)'!$D$27*12,J11*'Input sheet(dashboard)'!$E$8,0) -> 9489.233 | L11: =IF(B11<='Input sheet(dashboard)'!$D$27*12,'Input sheet(dashboard)'!$D$9*(1+'Input sheet(dashboard)'!$E$22)^B11,0) -> 3049.7939 | M11: =IF(B11=1,'Input sheet(dashboard)'!$D$3*'Input sheet(dashboard)'!$D$10,0) -> 0 | N11: =IF(B11='Input sheet(dashboard)'!$D$27*12,J11*'Input sheet(dashboard)'!$D$11,0) -> 0 | O11: =IF(SUM(F11:F22)>=150000,150000/12*'Input sheet(dashboard)'!$D$28,SUM(F11:F22)/12*'Input sheet(dashboard)'!$D$28) -> 1875 | Q11: =IF(B11<='Input sheet(dashboard)'!$D$27*12,'Input sheet(dashboard)'!$D$12/12,0) -> 192.5 | R11: =IF(B11<='Input sheet(dashboard)'!$D$27*12,('Input sheet(dashboard)'!$D$15/12)*(1+'Input sheet(dashboard)'!$E$22)^Calculations!B11,0) -> 338.86599 | S11: =IF(B11<='Input sheet(dashboard)'!$D$27*12,(E11+G11+K11+L11-O11+M11+Q11+R11),0) -> 54216.262 | U11: =IF(B11<='Input sheet(dashboard)'!$D$27*12,IF(S11<AD11,AD11-S11,0),0) -> 0 | V11: =IF(B11<='Input sheet(dashboard)'!$D$27*12,V10*(1+'Input sheet(dashboard)'!$E$25)+U11,0) -> 0 | W11: =IF(B11<='Input sheet(dashboard)'!$D$27*12,J11-I11+V11-N11,0) -> 1267234.4 | X11: =IF(B11<='Input sheet(dashboard)'!$D$27*12,'Input sheet(dashboard)'!$D$17*(1+'Input sheet(dashboard)'!$E$23)^(B11-1),0) -> 26652.872 | AB11: =IF(B11=1,'Input sheet(dashboard)'!$D$18*Calculations!X11,IF(Calculations!B11=12*'Input sheet(dashboard)'!$D$27,'Input sheet(dashboard)'!$D$18*-Calculations!X11,0)) -> 0 | AC11: =IF(B11<='Input sheet(dashboard)'!$D$27*12,IF(MOD(B10,'Input sheet(dashboard)'!$D$19*12),0,'Input sheet(dashboard)'!$D$20*(1+'Input sheet(dashboard)'!$E$22)^Calculations!B11),0) -> 0 | AD11: =X11+Y11+AB11+AC11 -> 26652.872 | AF11: =S11-AD11 -> 27563.389 | AG11: =IF(AF11>0,AF11,0) -> 27563.389 | AH11: =IF(B11<='Input sheet(dashboard)'!$D$27*12,AH10*(1+'Input sheet(dashboard)'!$E$25)+AG11," ") -> 1199445
B12: =B11+1 -> 9 | C12: 1 | D12: 9 | E12: =IF(C12<='Input sheet(dashboard)'!$D$6, -PMT('Input sheet(dashboard)'!$E$5,'Input sheet(dashboard)'!$D$6*12,'Input sheet(dashboard)'!$D$3*'Input sheet(dashboard)'!$D$4),0) -> 39834.138 | F12: =I11*'Input sheet(dashboard)'!$E$5 -> 28758.006 | G12: =IF(C12<='Input sheet(dashboard)'!$D$6,E12*'Input sheet(dashboard)'!$D$7,0) -> 3186.731 | H12: =E12-F12 -> 11076.132 | I12: =I11-H12 -> 7883426.9 | J12: =IF(B12<='Input sheet(dashboard)'!$D$27*12,'Input sheet(dashboard)'!$D$3*(1+'Input sheet(dashboard)'!$E$24)^B12,0) -> 9199063.4 | K12: =IF(B12<='Input sheet(dashboard)'!$D$27*12,J12*'Input sheet(dashboard)'!$E$8,0) -> 9527.8933 | L12: =IF(B12<='Input sheet(dashboard)'!$D$27*12,'Input sheet(dashboard)'!$D$9*(1+'Input sheet(dashboard)'!$E$22)^B12,0) -> 3056.076 | M12: =IF(B12=1,'Input sheet(dashboard)'!$D$3*'Input sheet(dashboard)'!$D$10,0) -> 0 | N12: =IF(B12='Input sheet(dashboard)'!$D$27*12,J12*'Input sheet(dashboard)'!$D$11,0) -> 0 | O12: =IF(SUM(F12:F23)>=150000,150000/12*'Input sheet(dashboard)'!$D$28,SUM(F12:F23)/12*'Input sheet(dashboard)'!$D$28) -> 1875 | Q12: =IF(B12<='Input sheet(dashboard)'!$D$27*12,'Input sheet(dashboard)'!$D$12/12,0) -> 192.5 | R12: =IF(B12<='Input sheet(dashboard)'!$D$27*12,('Input sheet(dashboard)'!$D$15/12)*(1+'Input sheet(dashboard)'!$E$22)^Calculations!B12,0) -> 339.564 | S12: =IF(B12<='Input sheet(dashboard)'!$D$27*12,(E12+G12+K12+L12-O12+M12+Q12+R12),0) -> 54261.902 | U12: =IF(B12<='Input sheet(dashboard)'!$D$27*12,IF(S12<AD12,AD12-S12,0),0) -> 0 | V12: =IF(B12<='Input sheet(dashboard)'!$D$27*12,V11*(1+'Input sheet(dashboard)'!$E$25)+U12,0) -> 0 | W12: =IF(B12<='Input sheet(dashboard)'!$D$27*12,J12-I12+V12-N12,0) -> 1315636.6 | X12: =IF(B12<='Input sheet(dashboard)'!$D$27*12,'Input sheet(dashboard)'!$D$17*(1+'Input sheet(dashboard)'!$E$23)^(B12-1),0) -> 26761.46 | AB12: =IF(B12=1,'Input sheet(dashboard)'!$D$18*Calculations!X12,IF(Calculations!B12=12*'Input sheet(dashboard)'!$D$27,'Input sheet(dashboard)'!$D$18*-Calculations!X12,0)) -> 0 | AC12: =IF(B12<='Input sheet(dashboard)'!$D$27*12,IF(MOD(B11,'Input sheet(dashboard)'!$D$19*12),0,'Input sheet(dashboard)'!$D$20*(1+'Input sheet(dashboard)'!$E$22)^Calculations!B12),0) -> 0 | AD12: =X12+Y12+AB12+AC12 -> 26761.46 | AF12: =S12-AD12 -> 27500.443 | AG12: =IF(AF12>0,AF12,0) -> 27500.443 | AH12: =IF(B12<='Input sheet(dashboard)'!$D$27*12,AH11*(1+'Input sheet(dashboard)'!$E$25)+AG12," ") -> 1234662.7
B13: =B12+1 -> 10 | C13: 1 | D13: 10 | E13: =IF(C13<='Input sheet(dashboard)'!$D$6, -PMT('Input sheet(dashboard)'!$E$5,'Input sheet(dashboard)'!$D$6*12,'Input sheet(dashboard)'!$D$3*'Input sheet(dashboard)'!$D$4),0) -> 39834.138 | F13: =I12*'Input sheet(dashboard)'!$E$5 -> 28717.658 | G13: =IF(C13<='Input sheet(dashboard)'!$D$6,E13*'Input sheet(dashboard)'!$D$7,0) -> 3186.731 | H13: =E13-F13 -> 11116.48 | I13: =I12-H13 -> 7872310.4 | J13: =IF(B13<='Input sheet(dashboard)'!$D$27*12,'Input sheet(dashboard)'!$D$3*(1+'Input sheet(dashboard)'!$E$24)^B13,0) -> 9236541.6 | K13: =IF(B13<='Input sheet(dashboard)'!$D$27*12,J13*'Input sheet(dashboard)'!$E$8,0) -> 9566.7111 | L13: =IF(B13<='Input sheet(dashboard)'!$D$27*12,'Input sheet(dashboard)'!$D$9*(1+'Input sheet(dashboard)'!$E$22)^B13,0) -> 3062.371 | M13: =IF(B13=1,'Input sheet(dashboard)'!$D$3*'Input sheet(dashboard)'!$D$10,0) -> 0 | N13: =IF(B13='Input sheet(dashboard)'!$D$27*12,J13*'Input sheet(dashboard)'!$D$11,0) -> 0 | O13: =IF(SUM(F13:F24)>=150000,150000/12*'Input sheet(dashboard)'!$D$28,SUM(F13:F24)/12*'Input sheet(dashboard)'!$D$28) -> 1875 | Q13: =IF(B13<='Input sheet(dashboard)'!$D$27*12,'Input sheet(dashboard)'!$D$12/12,0) -> 192.5 | R13: =IF(B13<='Input sheet(dashboard)'!$D$27*12,('Input sheet(dashboard)'!$D$15/12)*(1+'Input sheet(dashboard)'!$E$22)^Calculations!B13,0) -> 340.26345 | S13: =IF(B13<='Input sheet(dashboard)'!$D$27*12,(E13+G13+K13+L13-O13+M13+Q13+R13),0) -> 54307.715 | U13: =IF(B13<='Input sheet(dashboard)'!$D$27*12,IF(S13<AD13,AD13-S13,0),0) -> 0 | V13: =IF(B13<='Input sheet(dashboard)'!$D$27*12,V12*(1+'Input sheet(dashboard)'!$E$25)+U13,0) -> 0 | W13: =IF(B13<='Input sheet(dashboard)'!$D$27*12,J13-I13+V13-N13,0) -> 1364231.2 | X13: =IF(B13<='Input sheet(dashboard)'!$D$27*12,'Input sheet(dashboard)'!$D$17*(1+'Input sheet(dashboard)'!$E$23)^(B13-1),0) -> 26870.489 | AB13: =IF(B13=1,'Input sheet(dashboard)'!$D$18*Calculations!X13,IF(Calculations!B13=12*'Input sheet(dashboard)'!$D$27,'Input sheet(dashboard)'!$D$18*-Calculations!X13,0)) -> 0 | AC13: =IF(B13<='Input sheet(dashboard)'!$D$27*12,IF(MOD(B12,'Input sheet(dashboard)'!$D$19*12),0,'Input sheet(dashboard)'!$D$20*(1+'Input sheet(dashboard)'!$E$22)^Calculations!B13),0) -> 0 | AD13: =X13+Y13+AB13+AC13 -> 26870.489 | AF13: =S13-AD13 -> 27437.225 | AG13: =IF(AF13>0,AF13,0) -> 27437.225 | AH13: =IF(B13<='Input sheet(dashboard)'!$D$27*12,AH12*(1+'Input sheet(dashboard)'!$E$25)+AG13," ") -> 1270043.8
B14: =B13+1 -> 11 | C14: 1 | D14: 11 | E14: =IF(C14<='Input sheet(dashboard)'!$D$6, -PMT('Input sheet(dashboard)'!$E$5,'Input sheet(dashboard)'!$D$6*12,'Input sheet(dashboard)'!$D$3*'Input sheet(dashboard)'!$D$4),0) -> 39834.138 | F14: =I13*'Input sheet(dashboard)'!$E$5 -> 28677.163 | G14: =IF(C14<='Input sheet(dashboard)'!$D$6,E14*'Input sheet(dashboard)'!$D$7,0) -> 3186.731 | H14: =E14-F14 -> 11156.975 | I14: =I13-H14 -> 7861153.4 | J14: =IF(B14<='Input sheet(dashboard)'!$D$27*12,'Input sheet(dashboard)'!$D$3*(1+'Input sheet(dashboard)'!$E$24)^B14,0) -> 9274172.4 | K14: =IF(B14<='Input sheet(dashboard)'!$D$27*12,J14*'Input sheet(dashboard)'!$E$8,0) -> 9605.6871 | L14: =IF(B14<='Input sheet(dashboard)'!$D$27*12,'Input sheet(dashboard)'!$D$9*(1+'Input sheet(dashboard)'!$E$22)^B14,0) -> 3068.679 | M14: =IF(B14=1,'Input sheet(dashboard)'!$D$3*'Input sheet(dashboard)'!$D$10,0) -> 0 | N14: =IF(B14='Input sheet(dashboard)'!$D$27*12,J14*'Input sheet(dashboard)'!$D$11,0) -> 0 | O14: =IF(SUM(F14:F25)>=150000,150000/12*'Input sheet(dashboard)'!$D$28,SUM(F14:F25)/12*'Input sheet(dashboard)'!$D$28) -> 1875 | Q14: =IF(B14<='Input sheet(dashboard)'!$D$27*12,'Input sheet(dashboard)'!$D$12/12,0) -> 192.5 | R14: =IF(B14<='Input sheet(dashboard)'!$D$27*12,('Input sheet(dashboard)'!$D$15/12)*(1+'Input sheet(dashboard)'!$E$22)^Calculations!B14,0) -> 340.96434 | S14: =IF(B14<='Input sheet(dashboard)'!$D$27*12,(E14+G14+K14+L14-O14+M14+Q14+R14),0) -> 54353.699 | U14: =IF(B14<='Input sheet(dashboard)'!$D$27*12,IF(S14<AD14,AD14-S14,0),0) -> 0 | V14: =IF(B14<='Input sheet(dashboard)'!$D$27*12,V13*(1+'Input sheet(dashboard)'!$E$25)+U14,0) -> 0 | W14: =IF(B14<='Input sheet(dashboard)'!$D$27*12,J14-I14+V14-N14,0) -> 1413019 | X14: =IF(B14<='Input sheet(dashboard)'!$D$27*12,'Input sheet(dashboard)'!$D$17*(1+'Input sheet(dashboard)'!$E$23)^(B14-1),0) -> 26979.963 | AB14: =IF(B14=1,'Input sheet(dashboard)'!$D$18*Calculations!X14,IF(Calculations!B14=12*'Input sheet(dashboard)'!$D$27,'Input sheet(dashboard)'!$D$18*-Calculations!X14,0)) -> 0 | AC14: =IF(B14<='Input sheet(dashboard)'!$D$27*12,IF(MOD(B13,'Input sheet(dashboard)'!$D$19*12),0,'Input sheet(dashboard)'!$D$20*(1+'Input sheet(dashboard)'!$E$22)^Calculations!B14),0) -> 0 | AD14: =X14+Y14+AB14+AC14 -> 26979.963 | AF14: =S14-AD14 -> 27373.737 | AG14: =IF(AF14>0,AF14,0) -> 27373.737 | AH14: =IF(B14<='Input sheet(dashboard)'!$D$27*12,AH13*(1+'Input sheet(dashboard)'!$E$25)+AG14," ") -> 1305589
B15: =B14+1 -> 12 | C15: 1 | D15: 12 | E15: =IF(C15<='Input sheet(dashboard)'!$D$6, -PMT('Input sheet(dashboard)'!$E$5,'Input sheet(dashboard)'!$D$6*12,'Input sheet(dashboard)'!$D$3*'Input sheet(dashboard)'!$D$4),0) -> 39834.138 | F15: =I14*'Input sheet(dashboard)'!$E$5 -> 28636.52 | G15: =IF(C15<='Input sheet(dashboard)'!$D$6,E15*'Input sheet(dashboard)'!$D$7,0) -> 3186.731 | H15: =E15-F15 -> 11197.618 | I15: =I14-H15 -> 7849955.8 | J15: =IF(B15<='Input sheet(dashboard)'!$D$27*12,'Input sheet(dashboard)'!$D$3*(1+'Input sheet(dashboard)'!$E$24)^B15,0) -> 9311956.5 | K15: =IF(B15<='Input sheet(dashboard)'!$D$27*12,J15*'Input sheet(dashboard)'!$E$8,0) -> 9644.8218 | L15: =IF(B15<='Input sheet(dashboard)'!$D$27*12,'Input sheet(dashboard)'!$D$9*(1+'Input sheet(dashboard)'!$E$22)^B15,0) -> 3075 | M15: =IF(B15=1,'Input sheet(dashboard)'!$D$3*'Input sheet(dashboard)'!$D$10,0) -> 0 | N15: =IF(B15='Input sheet(dashboard)'!$D$27*12,J15*'Input sheet(dashboard)'!$D$11,0) -> 0 | O15: =IF(SUM(F15:F26)>=150000,150000/12*'Input sheet(dashboard)'!$D$28,SUM(F15:F26)/12*'Input sheet(dashboard)'!$D$28) -> 1875 | P15: =IF(D15=12,IF(SUM(F4:F16)>=150000,150000*0.15,SUM(F4:F16)*0.15),0) -> 22500 | Q15: =IF(B15<='Input sheet(dashboard)'!$D$27*12,'Input sheet(dashboard)'!$D$12/12,0) -> 192.5 | R15: =IF(B15<='Input sheet(dashboard)'!$D$27*12,('Input sheet(dashboard)'!$D$15/12)*(1+'Input sheet(dashboard)'!$E$22)^Calculations!B15,0) -> 341.66667 | S15: =IF(B15<='Input sheet(dashboard)'!$D$27*12,(E15+G15+K15+L15-O15+M15+Q15+R15),0) -> 54399.857 | T15: =IF(B15<='Input sheet(dashboard)'!$D$27*12,IF(D15=12,SUM(S4:S15),0),0) -> 738474.94 | U15: =IF(B15<='Input sheet(dashboard)'!$D$27*12,IF(S15<AD15,AD15-S15,0),0) -> 0 | V15: =IF(B15<='Input sheet(dashboard)'!$D$27*12,V14*(1+'Input sheet(dashboard)'!$E$25)+U15,0) -> 0 | W15: =IF(B15<='Input sheet(dashboard)'!$D$27*12,J15-I15+V15-N15,0) -> 1462000.7 | X15: =IF(B15<='Input sheet(dashboard)'!$D$27*12,'Input sheet(dashboard)'!$D$17*(1+'Input sheet(dashboard)'!$E$23)^(B15-1),0) -> 27089.882 | AB15: =IF(B15=1,'Input sheet(dashboard)'!$D$18*Calculations!X15,IF(Calculations!B15=12*'Input sheet(dashboard)'!$D$27,'Input sheet(dashboard)'!$D$18*-Calculations!X15,0)) -> 0 | AC15: =IF(B15<='Input sheet(dashboard)'!$D$27*12,IF(MOD(B14,'Input sheet(dashboard)'!$D$19*12),0,'Input sheet(dashboard)'!$D$20*(1+'Input sheet(dashboard)'!$E$22)^Calculations!B15),0) -> 0 | AD15: =X15+Y15+AB15+AC15 -> 27089.882 | AE15: =IF(B15<='Input sheet(dashboard)'!$D$27*12,IF(D15=12,SUM(AD4:AD15),0),0) -> 369731.12 | AF15: =S15-AD15 -> 27309.975 | AG15: =IF(AF15>0,AF15,0) -> 27309.975 | AH15: =IF(B15<='Input sheet(dashboard)'!$D$27*12,AH14*(1+'Input sheet(dashboard)'!$E$25)+AG15," ") -> 1341299.2
B16: =B15+1 -> 13 | C16: =C4+1 -> 2 | D16: =D4 -> 1 | E16: =IF(C16<='Input sheet(dashboard)'!$D$6, -PMT('Input sheet(dashboard)'!$E$5,'Input sheet(dashboard)'!$D$6*12,'Input sheet(dashboard)'!$D$3*'Input sheet(dashboard)'!$D$4),0) -> 39834.138 | F16: =I15*'Input sheet(dashboard)'!$E$5 -> 28595.73 | G16: =IF(C16<='Input sheet(dashboard)'!$D$6,E16*'Input sheet(dashboard)'!$D$7,0) -> 3186.731 | H16: =E16-F16 -> 11238.408 | I16: =I15-H16 -> 7838717.4 | J16: =IF(B16<='Input sheet(dashboard)'!$D$27*12,'Input sheet(dashboard)'!$D$3*(1+'Input sheet(dashboard)'!$E$24)^B16,0) -> 9349894.6 | K16: =IF(B16<='Input sheet(dashboard)'!$D$27*12,J16*'Input sheet(dashboard)'!$E$8,0) -> 9684.116 | L16: =IF(B16<='Input sheet(dashboard)'!$D$27*12,'Input sheet(dashboard)'!$D$9*(1+'Input sheet(dashboard)'!$E$22)^B16,0) -> 3081.334 | M16: =IF(B16=1,'Input sheet(dashboard)'!$D$3*'Input sheet(dashboard)'!$D$10,0) -> 0 | N16: =IF(B16='Input sheet(dashboard)'!$D$27*12,J16*'Input sheet(dashboard)'!$D$11,0) -> 0 | O16: =IF(SUM(F16:F27)>=150000,150000/12*'Input sheet(dashboard)'!$D$28,SUM(F16:F27)/12*'Input sheet(dashboard)'!$D$28) -> 1875 | P16: =IF(D16=12,IF(SUM(F5:F17)>=150000,150000*0.15,SUM(F5:F17)*0.15),0) -> 0 | Q16: =IF(B16<='Input sheet(dashboard)'!$D$27*12,'Input sheet(dashboard)'!$D$12/12,0) -> 192.5 | R16: =IF(B16<='Input sheet(dashboard)'!$D$27*12,('Input sheet(dashboard)'!$D$15/12)*(1+'Input sheet(dashboard)'!$E$22)^Calculations!B16,0) -> 342.37044 | S16: =IF(B16<='Input sheet(dashboard)'!$D$27*12,(E16+G16+K16+L16-O16+M16+Q16+R16),0) -> 54446.189 | T16: =IF(B16<='Input sheet(dashboard)'!$D$27*12,IF(D16=12,SUM(S5:S16),0),0) -> 0 | U16: =IF(B16<='Input sheet(dashboard)'!$D$27*12,IF(S16<AD16,AD16-S16,0),0) -> 0 | V16: =IF(B16<='Input sheet(dashboard)'!$D$27*12,V15*(1+'Input sheet(dashboard)'!$E$25)+U16,0) -> 0 | W16: =IF(B16<='Input sheet(dashboard)'!$D$27*12,J16-I16+V16-N16,0) -> 1511177.2 | X16: =IF(B16<='Input sheet(dashboard)'!$D$27*12,'Input sheet(dashboard)'!$D$17*(1+'Input sheet(dashboard)'!$E$23)^(B16-1),0) -> 27200.25 | AB16: =IF(B16=1,'Input sheet(dashboard)'!$D$18*Calculations!X16,IF(Calculations!B16=12*'Input sheet(dashboard)'!$D$27,'Input sheet(dashboard)'!$D$18*-Calculations!X16,0)) -> 0 | AC16: =IF(B16<='Input sheet(dashboard)'!$D$27*12,IF(MOD(B15,'Input sheet(dashboard)'!$D$19*12),0,'Input sheet(dashboard)'!$D$20*(1+'Input sheet(dashboard)'!$E$22)^Calculations!B16),0) -> 0 | AD16: =X16+Y16+AB16+AC16 -> 27200.25 | AE16: =IF(B16<='Input sheet(dashboard)'!$D$27*12,IF(D16=12,SUM(AD5:AD16),0),0) -> 0 | AF16: =S16-AD16 -> 27245.939 | AG16: =IF(AF16>0,AF16,0) -> 27245.939 | AH16: =IF(B16<='Input sheet(dashboard)'!$D$27*12,AH15*(1+'Input sheet(dashboard)'!$E$25)+AG16," ") -> 1377175.1
B17: =B16+1 -> 14 | C17: =C5+1 -> 2 | D17: =D5 -> 2 | E17: =IF(C17<='Input sheet(dashboard)'!$D$6, -PMT('Input sheet(dashboard)'!$E$5,'Input sheet(dashboard)'!$D$6*12,'Input sheet(dashboard)'!$D$3*'Input sheet(dashboard)'!$D$4),0) -> 39834.138 | F17: =I16*'Input sheet(dashboard)'!$E$5 -> 28554.791 | G17: =IF(C17<='Input sheet(dashboard)'!$D$6,E17*'Input sheet(dashboard)'!$D$7,0) -> 3186.731 | H17: =E17-F17 -> 11279.347 | I17: =I16-H17 -> 7827438 | J17: =IF(B17<='Input sheet(dashboard)'!$D$27*12,'Input sheet(dashboard)'!$D$3*(1+'Input sheet(dashboard)'!$E$24)^B17,0) -> 9387987.2 | K17: =IF(B17<='Input sheet(dashboard)'!$D$27*12,J17*'Input sheet(dashboard)'!$E$8,0) -> 9723.5703 | L17: =IF(B17<='Input sheet(dashboard)'!$D$27*12,'Input sheet(dashboard)'!$D$9*(1+'Input sheet(dashboard)'!$E$22)^B17,0) -> 3087.681 | M17: =IF(B17=1,'Input sheet(dashboard)'!$D$3*'Input sheet(dashboard)'!$D$10,0) -> 0 | N17: =IF(B17='Input sheet(dashboard)'!$D$27*12,J17*'Input sheet(dashboard)'!$D$11,0) -> 0 | O17: =IF(SUM(F17:F28)>=150000,150000/12*'Input sheet(dashboard)'!$D$28,SUM(F17:F28)/12*'Input sheet(dashboard)'!$D$28) -> 1875 | P17: =IF(D17=12,IF(SUM(F6:F18)>=150000,150000*0.15,SUM(F6:F18)*0.15),0) -> 0 | Q17: =IF(B17<='Input sheet(dashboard)'!$D$27*12,'Input sheet(dashboard)'!$D$12/12,0) -> 192.5 | R17: =IF(B17<='Input sheet(dashboard)'!$D$27*12,('Input sheet(dashboard)'!$D$15/12)*(1+'Input sheet(dashboard)'!$E$22)^Calculations!B17,0) -> 343.07567 | S17: =IF(B17<='Input sheet(dashboard)'!$D$27*12,(E17+G17+K17+L17-O17+M17+Q17+R17),0) -> 54492.696 | T17: =IF(B17<='Input sheet(dashboard)'!$D$27*12,IF(D17=12,SUM(S6:S17),0),0) -> 0 | U17: =IF(B17<='Input sheet(dashboard)'!$D$27*12,IF(S17<AD17,AD17-S17,0),0) -> 0 | V17: =IF(B17<='Input sheet(dashboard)'!$D$27*12,V16*(1+'Input sheet(dashboard)'!$E$25)+U17,0) -> 0 | W17: =IF(B17<='Input sheet(dashboard)'!$D$27*12,J17-I17+V17-N17,0) -> 1560549.1 | X17: =IF(B17<='Input sheet(dashboard)'!$D$27*12,'Input sheet(dashboard)'!$D$17*(1+'Input sheet(dashboard)'!$E$23)^(B17-1),0) -> 27311.067 | AB17: =IF(B17=1,'Input sheet(dashboard)'!$D$18*Calculations!X17,IF(Calculations!B17=12*'Input sheet(dashboard)'!$D$27,'Input sheet(dashboard)'!$D$18*-Calculations!X17,0)) -> 0 | AC17: =IF(B17<='Input sheet(dashboard)'!$D$27*12,IF(MOD(B16,'Input sheet(dashboard)'!$D$19*12),0,'Input sheet(dashboard)'!$D$20*(1+'Input sheet(dashboard)'!$E$22)^Calculations!B17),0) -> 0 | AD17: =X17+Y17+AB17+AC17 -> 27311.067 | AE17: =IF(B17<='Input sheet(dashboard)'!$D$27*12,IF(D17=12,SUM(AD6:AD17),0),0) -> 0 | AF17: =S17-AD17 -> 27181.629 | AG17: =IF(AF17>0,AF17,0) -> 27181.629 | AH17: =IF(B17<='Input sheet(dashboard)'!$D$27*12,AH16*(1+'Input sheet(dashboard)'!$E$25)+AG17," ") -> 1413217.5
B18: =B17+1 -> 15 | C18: =C6+1 -> 2 | D18: =D6 -> 3 | E18: =IF(C18<='Input sheet(dashboard)'!$D$6, -PMT('Input sheet(dashboard)'!$E$5,'Input sheet(dashboard)'!$D$6*12,'Input sheet(dashboard)'!$D$3*'Input sheet(dashboard)'!$D$4),0) -> 39834.138 | F18: =I17*'Input sheet(dashboard)'!$E$5 -> 28513.702 | G18: =IF(C18<='Input sheet(dashboard)'!$D$6,E18*'Input sheet(dashboard)'!$D$7,0) -> 3186.731 | H18: =E18-F18 -> 11320.436 | I18: =I17-H18 -> 7816117.6 | J18: =IF(B18<='Input sheet(dashboard)'!$D$27*12,'Input sheet(dashboard)'!$D$3*(1+'Input sheet(dashboard)'!$E$24)^B18,0) -> 9426235 | K18: =IF(B18<='Input sheet(dashboard)'!$D$27*12,J18*'Input sheet(dashboard)'!$E$8,0) -> 9763.1853 | L18: =IF(B18<='Input sheet(dashboard)'!$D$27*12,'Input sheet(dashboard)'!$D$9*(1+'Input sheet(dashboard)'!$E$22)^B18,0) -> 3094.0412 | M18: =IF(B18=1,'Input sheet(dashboard)'!$D$3*'Input sheet(dashboard)'!$D$10,0) -> 0 | N18: =IF(B18='Input sheet(dashboard)'!$D$27*12,J18*'Input sheet(dashboard)'!$D$11,0) -> 0 | O18: =IF(SUM(F18:F29)>=150000,150000/12*'Input sheet(dashboard)'!$D$28,SUM(F18:F29)/12*'Input sheet(dashboard)'!$D$28) -> 1875 | P18: =IF(D18=12,IF(SUM(F7:F19)>=150000,150000*0.15,SUM(F7:F19)*0.15),0) -> 0 | Q18: =IF(B18<='Input sheet(dashboard)'!$D$27*12,'Input sheet(dashboard)'!$D$12/12,0) -> 192.5 | R18: =IF(B18<='Input sheet(dashboard)'!$D$27*12,('Input sheet(dashboard)'!$D$15/12)*(1+'Input sheet(dashboard)'!$E$22)^Calculations!B18,0) -> 343.78235 | S18: =IF(B18<='Input sheet(dashboard)'!$D$27*12,(E18+G18+K18+L18-O18+M18+Q18+R18),0) -> 54539.378 | T18: =IF(B18<='Input sheet(dashboard)'!$D$27*12,IF(D18=12,SUM(S7:S18),0),0) -> 0 | U18: =IF(B18<='Input sheet(dashboard)'!$D$27*12,IF(S18<AD18,AD18-S18,0),0) -> 0 | V18: =IF(B18<='Input sheet(dashboard)'!$D$27*12,V17*(1+'Input sheet(dashboard)'!$E$25)+U18,0) -> 0 | W18: =IF(B18<='Input sheet(dashboard)'!$D$27*12,J18-I18+V18-N18,0) -> 1610117.4 | X18: =IF(B18<='Input sheet(dashboard)'!$D$27*12,'Input sheet(dashboard)'!$D$17*(1+'Input sheet(dashboard)'!$E$23)^(B18-1),0) -> 27422.336 | AB18: =IF(B18=1,'Input sheet(dashboard)'!$D$18*Calculations!X18,IF(Calculations!B18=12*'Input sheet(dashboard)'!$D$27,'Input sheet(dashboard)'!$D$18*-Calculations!X18,0)) -> 0 | AC18: =IF(B18<='Input sheet(dashboard)'!$D$27*12,IF(MOD(B17,'Input sheet(dashboard)'!$D$19*12),0,'Input sheet(dashboard)'!$D$20*(1+'Input sheet(dashboard)'!$E$22)^Calculations!B18),0) -> 0 | AD18: =X18+Y18+AB18+AC18 -> 27422.336 | AE18: =IF(B18<='Input sheet(dashboard)'!$D$27*12,IF(D18=12,SUM(AD7:AD18),0),0) -> 0 | AF18: =S18-AD18 -> 27117.042 | AG18: =IF(AF18>0,AF18,0) -> 27117.042 | AH18: =IF(B18<='Input sheet(dashboard)'!$D$27*12,AH17*(1+'Input sheet(dashboard)'!$E$25)+AG18," ") -> 1449427.3
B19: =B18+1 -> 16 | C19: =C7+1 -> 2 | D19: =D7 -> 4 | E19: =IF(C19<='Input sheet(dashboard)'!$D$6, -PMT('Input sheet(dashboard)'!$E$5,'Input sheet(dashboard)'!$D$6*12,'Input sheet(dashboard)'!$D$3*'Input sheet(dashboard)'!$D$4),0) -> 39834.138 | F19: =I18*'Input sheet(dashboard)'!$E$5 -> 28472.464 | G19: =IF(C19<='Input sheet(dashboard)'!$D$6,E19*'Input sheet(dashboard)'!$D$7,0) -> 3186.731 | H19: =E19-F19 -> 11361.673 | I19: =I18-H19 -> 7804755.9 | J19: =IF(B19<='Input sheet(dashboard)'!$D$27*12,'Input sheet(dashboard)'!$D$3*(1+'Input sheet(dashboard)'!$E$24)^B19,0) -> 9464638.7 | K19: =IF(B19<='Input sheet(dashboard)'!$D$27*12,J19*'Input sheet(dashboard)'!$E$8,0) -> 9802.9618 | L19: =IF(B19<='Input sheet(dashboard)'!$D$27*12,'Input sheet(dashboard)'!$D$9*(1+'Input sheet(dashboard)'!$E$22)^B19,0) -> 3100.4144 | M19: =IF(B19=1,'Input sheet(dashboard)'!$D$3*'Input sheet(dashboard)'!$D$10,0) -> 0 | N19: =IF(B19='Input sheet(dashboard)'!$D$27*12,J19*'Input sheet(dashboard)'!$D$11,0) -> 0 | O19: =IF(SUM(F19:F30)>=150000,150000/12*'Input sheet(dashboard)'!$D$28,SUM(F19:F30)/12*'Input sheet(dashboard)'!$D$28) -> 1875 | P19: =IF(D19=12,IF(SUM(F8:F20)>=150000,150000*0.15,SUM(F8:F20)*0.15),0) -> 0 | Q19: =IF(B19<='Input sheet(dashboard)'!$D$27*12,'Input sheet(dashboard)'!$D$12/12,0) -> 192.5 | R19: =IF(B19<='Input sheet(dashboard)'!$D$27*12,('Input sheet(dashboard)'!$D$15/12)*(1+'Input sheet(dashboard)'!$E$22)^Calculations!B19,0) -> 344.49049 | S19: =IF(B19<='Input sheet(dashboard)'!$D$27*12,(E19+G19+K19+L19-O19+M19+Q19+R19),0) -> 54586.236 | T19: =IF(B19<='Input sheet(dashboard)'!$D$27*12,IF(D19=12,SUM(S8:S19),0),0) -> 0 | U19: =IF(B19<='Input sheet(dashboard)'!$D$27*12,IF(S19<AD19,AD19-S19,0),0) -> 0 | V19: =IF(B19<='Input sheet(dashboard)'!$D$27*12,V18*(1+'Input sheet(dashboard)'!$E$25)+U19,0) -> 0 | W19: =IF(B19<='Input sheet(dashboard)'!$D$27*12,J19-I19+V19-N19,0) -> 1659882.7 | X19: =IF(B19<='Input sheet(dashboard)'!$D$27*12,'Input sheet(dashboard)'!$D$17*(1+'Input sheet(dashboard)'!$E$23)^(B19-1),0) -> 27534.058 | AB19: =IF(B19=1,'Input sheet(dashboard)'!$D$18*Calculations!X19,IF(Calculations!B19=12*'Input sheet(dashboard)'!$D$27,'Input sheet(dashboard)'!$D$18*-Calculations!X19,0)) -> 0 | AC19: =IF(B19<='Input sheet(dashboard)'!$D$27*12,IF(MOD(B18,'Input sheet(dashboard)'!$D$19*12),0,'Input sheet(dashboard)'!$D$20*(1+'Input sheet(dashboard)'!$E$22)^Calculations!B19),0) -> 0 | AD19: =X19+Y19+AB19+AC19 -> 27534.058 | AE19: =IF(B19<='Input sheet(dashboard)'!$D$27*12,IF(D19=12,SUM(AD8:AD19),0),0) -> 0 | AF19: =S19-AD19 -> 27052.178 | AG19: =IF(AF19>0,AF19,0) -> 27052.178 | AH19: =IF(B19<='Input sheet(dashboard)'!$D$27*12,AH18*(1+'Input sheet(dashboard)'!$E$25)+AG19," ") -> 1485805.1
B20: =B19+1 -> 17 | C20: =C8+1 -> 2 | D20: =D8 -> 5 | E20: =IF(C20<='Input sheet(dashboard)'!$D$6, -PMT('Input sheet(dashboard)'!$E$5,'Input sheet(dashboard)'!$D$6*12,'Input sheet(dashboard)'!$D$3*'Input sheet(dashboard)'!$D$4),0) -> 39834.138 | F20: =I19*'Input sheet(dashboard)'!$E$5 -> 28431.076 | G20: =IF(C20<='Input sheet(dashboard)'!$D$6,E20*'Input sheet(dashboard)'!$D$7,0) -> 3186.731 | H20: =E20-F20 -> 11403.062 | I20: =I19-H20 -> 7793352.9 | J20: =IF(B20<='Input sheet(dashboard)'!$D$27*12,'Input sheet(dashboard)'!$D$3*(1+'Input sheet(dashboard)'!$E$24)^B20,0) -> 9503198.8 | K20: =IF(B20<='Input sheet(dashboard)'!$D$27*12,J20*'Input sheet(dashboard)'!$E$8,0) -> 9842.9003 | L20: =IF(B20<='Input sheet(dashboard)'!$D$27*12,'Input sheet(dashboard)'!$D$9*(1+'Input sheet(dashboard)'!$E$22)^B20,0) -> 3106.8007 | M20: =IF(B20=1,'Input sheet(dashboard)'!$D$3*'Input sheet(dashboard)'!$D$10,0) -> 0 | N20: =IF(B20='Input sheet(dashboard)'!$D$27*12,J20*'Input sheet(dashboard)'!$D$11,0) -> 0 | O20: =IF(SUM(F20:F31)>=150000,150000/12*'Input sheet(dashboard)'!$D$28,SUM(F20:F31)/12*'Input sheet(dashboard)'!$D$28) -> 1875 | P20: =IF(D20=12,IF(SUM(F9:F21)>=150000,150000*0.15,SUM(F9:F21)*0.15),0) -> 0 | Q20: =IF(B20<='Input sheet(dashboard)'!$D$27*12,'Input sheet(dashboard)'!$D$12/12,0) -> 192.5 | R20: =IF(B20<='Input sheet(dashboard)'!$D$27*12,('Input sheet(dashboard)'!$D$15/12)*(1+'Input sheet(dashboard)'!$E$22)^Calculations!B20,0) -> 345.20008 | S20: =IF(B20<='Input sheet(dashboard)'!$D$27*12,(E20+G20+K20+L20-O20+M20+Q20+R20),0) -> 54633.27 | T20: =IF(B20<='Input sheet(dashboard)'!$D$27*12,IF(D20=12,SUM(S9:S20),0),0) -> 0 | U20: =IF(B20<='Input sheet(dashboard)'!$D$27*12,IF(S20<AD20,AD20-S20,0),0) -> 0 | V20: =IF(B20<='Input sheet(dashboard)'!$D$27*12,V19*(1+'Input sheet(dashboard)'!$E$25)+U20,0) -> 0 | W20: =IF(B20<='Input sheet(dashboard)'!$D$27*12,J20-I20+V20-N20,0) -> 1709845.9 | X20: =IF(B20<='Input sheet(dashboard)'!$D$27*12,'Input sheet(dashboard)'!$D$17*(1+'Input sheet(dashboard)'!$E$23)^(B20-1),0) -> 27646.235 | AB20: =IF(B20=1,'Input sheet(dashboard)'!$D$18*Calculations!X20,IF(Calculations!B20=12*'Input sheet(dashboard)'!$D$27,'Input sheet(dashboard)'!$D$18*-Calculations!X20,0)) -> 0 | AC20: =IF(B20<='Input sheet(dashboard)'!$D$27*12,IF(MOD(B19,'Input sheet(dashboard)'!$D$19*12),0,'Input sheet(dashboard)'!$D$20*(1+'Input sheet(dashboard)'!$E$22)^Calculations!B20),0) -> 0 | AD20: =X20+Y20+AB20+AC20 -> 27646.235 | AE20: =IF(B20<='Input sheet(dashboard)'!$D$27*12,IF(D20=12,SUM(AD9:AD20),0),0) -> 0 | AF20: =S20-AD20 -> 26987.035 | AG20: =IF(AF20>0,AF20,0) -> 26987.035 | AH20: =IF(B20<='Input sheet(dashboard)'!$D$27*12,AH19*(1+'Input sheet(dashboard)'!$E$25)+AG20," ") -> 1522351.8
B21: =B20+1 -> 18 | C21: =C9+1 -> 2 | D21: =D9 -> 6 | E21: =IF(C21<='Input sheet(dashboard)'!$D$6, -PMT('Input sheet(dashboard)'!$E$5,'Input sheet(dashboard)'!$D$6*12,'Input sheet(dashboard)'!$D$3*'Input sheet(dashboard)'!$D$4),0) -> 39834.138 | F21: =I20*'Input sheet(dashboard)'!$E$5 -> 28389.537 | G21: =IF(C21<='Input sheet(dashboard)'!$D$6,E21*'Input sheet(dashboard)'!$D$7,0) -> 3186.731 | H21: =E21-F21 -> 11444.601 | I21: =I20-H21 -> 7781908.3 | J21: =IF(B21<='Input sheet(dashboard)'!$D$27*12,'Input sheet(dashboard)'!$D$3*(1+'Input sheet(dashboard)'!$E$24)^B21,0) -> 9541916 | K21: =IF(B21<='Input sheet(dashboard)'!$D$27*12,J21*'Input sheet(dashboard)'!$E$8,0) -> 9883.0014 | L21: =IF(B21<='Input sheet(dashboard)'!$D$27*12,'Input sheet(dashboard)'!$D$9*(1+'Input sheet(dashboard)'!$E$22)^B21,0) -> 3113.2002 | M21: =IF(B21=1,'Input sheet(dashboard)'!$D$3*'Input sheet(dashboard)'!$D$10,0) -> 0 | N21: =IF(B21='Input sheet(dashboard)'!$D$27*12,J21*'Input sheet(dashboard)'!$D$11,0) -> 0 | O21: =IF(SUM(F21:F32)>=150000,150000/12*'Input sheet(dashboard)'!$D$28,SUM(F21:F32)/12*'Input sheet(dashboard)'!$D$28) -> 1875 | P21: =IF(D21=12,IF(SUM(F10:F22)>=150000,150000*0.15,SUM(F10:F22)*0.15),0) -> 0 | Q21: =IF(B21<='Input sheet(dashboard)'!$D$27*12,'Input sheet(dashboard)'!$D$12/12,0) -> 192.5 | R21: =IF(B21<='Input sheet(dashboard)'!$D$27*12,('Input sheet(dashboard)'!$D$15/12)*(1+'Input sheet(dashboard)'!$E$22)^Calculations!B21,0) -> 345.91114 | S21: =IF(B21<='Input sheet(dashboard)'!$D$27*12,(E21+G21+K21+L21-O21+M21+Q21+R21),0) -> 54680.482 | T21: =IF(B21<='Input sheet(dashboard)'!$D$27*12,IF(D21=12,SUM(S10:S21),0),0) -> 0 | U21: =IF(B21<='Input sheet(dashboard)'!$D$27*12,IF(S21<AD21,AD21-S21,0),0) -> 0 | V21: =IF(B21<='Input sheet(dashboard)'!$D$27*12,V20*(1+'Input sheet(dashboard)'!$E$25)+U21,0) -> 0 | W21: =IF(B21<='Input sheet(dashboard)'!$D$27*12,J21-I21+V21-N21,0) -> 1760007.7 | X21: =IF(B21<='Input sheet(dashboard)'!$D$27*12,'Input sheet(dashboard)'!$D$17*(1+'Input sheet(dashboard)'!$E$23)^(B21-1),0) -> 27758.869 | AB21: =IF(B21=1,'Input sheet(dashboard)'!$D$18*Calculations!X21,IF(Calculations!B21=12*'Input sheet(dashboard)'!$D$27,'Input sheet(dashboard)'!$D$18*-Calculations!X21,0)) -> 0 | AC21: =IF(B21<='Input sheet(dashboard)'!$D$27*12,IF(MOD(B20,'Input sheet(dashboard)'!$D$19*12),0,'Input sheet(dashboard)'!$D$20*(1+'Input sheet(dashboard)'!$E$22)^Calculations!B21),0) -> 0 | AD21: =X21+Y21+AB21+AC21 -> 27758.869 | AE21: =IF(B21<='Input sheet(dashboard)'!$D$27*12,IF(D21=12,SUM(AD10:AD21),0),0) -> 0 | AF21: =S21-AD21 -> 26921.613 | AG21: =IF(AF21>0,AF21,0) -> 26921.613 | AH21: =IF(B21<='Input sheet(dashboard)'!$D$27*12,AH20*(1+'Input sheet(dashboard)'!$E$25)+AG21," ") -> 1559068.3
B22: =B21+1 -> 19 | C22: =C10+1 -> 2 | D22: =D10 -> 7 | E22: =IF(C22<='Input sheet(dashboard)'!$D$6, -PMT('Input sheet(dashboard)'!$E$5,'Input sheet(dashboard)'!$D$6*12,'Input sheet(dashboard)'!$D$3*'Input sheet(dashboard)'!$D$4),0) -> 39834.138 | F22: =I21*'Input sheet(dashboard)'!$E$5 -> 28347.847 | G22: =IF(C22<='Input sheet(dashboard)'!$D$6,E22*'Input sheet(dashboard)'!$D$7,0) -> 3186.731 | H22: =E22-F22 -> 11486.291 | I22: =I21-H22 -> 7770422 | J22: =IF(B22<='Input sheet(dashboard)'!$D$27*12,'Input sheet(dashboard)'!$D$3*(1+'Input sheet(dashboard)'!$E$24)^B22,0) -> 9580790.9 | K22: =IF(B22<='Input sheet(dashboard)'!$D$27*12,J22*'Input sheet(dashboard)'!$E$8,0) -> 9923.266 | L22: =IF(B22<='Input sheet(dashboard)'!$D$27*12,'Input sheet(dashboard)'!$D$9*(1+'Input sheet(dashboard)'!$E$22)^B22,0) -> 3119.6129 | M22: =IF(B22=1,'Input sheet(dashboard)'!$D$3*'Input sheet(dashboard)'!$D$10,0) -> 0 | N22: =IF(B22='Input sheet(dashboard)'!$D$27*12,J22*'Input sheet(dashboard)'!$D$11,0) -> 0 | O22: =IF(SUM(F22:F33)>=150000,150000/12*'Input sheet(dashboard)'!$D$28,SUM(F22:F33)/12*'Input sheet(dashboard)'!$D$28) -> 1875 | P22: =IF(D22=12,IF(SUM(F11:F23)>=150000,150000*0.15,SUM(F11:F23)*0.15),0) -> 0 | Q22: =IF(B22<='Input sheet(dashboard)'!$D$27*12,'Input sheet(dashboard)'!$D$12/12,0) -> 192.5 | R22: =IF(B22<='Input sheet(dashboard)'!$D$27*12,('Input sheet(dashboard)'!$D$15/12)*(1+'Input sheet(dashboard)'!$E$22)^Calculations!B22,0) -> 346.62366 | S22: =IF(B22<='Input sheet(dashboard)'!$D$27*12,(E22+G22+K22+L22-O22+M22+Q22+R22),0) -> 54727.872 | T22: =IF(B22<='Input sheet(dashboard)'!$D$27*12,IF(D22=12,SUM(S11:S22),0),0) -> 0 | U22: =IF(B22<='Input sheet(dashboard)'!$D$27*12,IF(S22<AD22,AD22-S22,0),0) -> 0 | V22: =IF(B22<='Input sheet(dashboard)'!$D$27*12,V21*(1+'Input sheet(dashboard)'!$E$25)+U22,0) -> 0 | W22: =IF(B22<='Input sheet(dashboard)'!$D$27*12,J22-I22+V22-N22,0) -> 1810368.9 | X22: =IF(B22<='Input sheet(dashboard)'!$D$27*12,'Input sheet(dashboard)'!$D$17*(1+'Input sheet(dashboard)'!$E$23)^(B22-1),0) -> 27871.962 | AB22: =IF(B22=1,'Input sheet(dashboard)'!$D$18*Calculations!X22,IF(Calculations!B22=12*'Input sheet(dashboard)'!$D$27,'Input sheet(dashboard)'!$D$18*-Calculations!X22,0)) -> 0 | AC22: =IF(B22<='Input sheet(dashboard)'!$D$27*12,IF(MOD(B21,'Input sheet(dashboard)'!$D$19*12),0,'Input sheet(dashboard)'!$D$20*(1+'Input sheet(dashboard)'!$E$22)^Calculations!B22),0) -> 0 | AD22: =X22+Y22+AB22+AC22 -> 27871.962 | AE22: =IF(B22<='Input sheet(dashboard)'!$D$27*12,IF(D22=12,SUM(AD11:AD22),0),0) -> 0 | AF22: =S22-AD22 -> 26855.909 | AG22: =IF(AF22>0,AF22,0) -> 26855.909 | AH22: =IF(B22<='Input sheet(dashboard)'!$D$27*12,AH21*(1+'Input sheet(dashboard)'!$E$25)+AG22," ") -> 1595955.3
B23: =B22+1 -> 20 | C23: =C11+1 -> 2 | D23: =D11 -> 8 | E23: =IF(C23<='Input sheet(dashboard)'!$D$6, -PMT('Input sheet(dashboard)'!$E$5,'Input sheet(dashboard)'!$D$6*12,'Input sheet(dashboard)'!$D$3*'Input sheet(dashboard)'!$D$4),0) -> 39834.138 | F23: =I22*'Input sheet(dashboard)'!$E$5 -> 28306.005 | G23: =IF(C23<='Input sheet(dashboard)'!$D$6,E23*'Input sheet(dashboard)'!$D$7,0) -> 3186.731 | H23: =E23-F23 -> 11528.133 | I23: =I22-H23 -> 7758893.9 | J23: =IF(B23<='Input sheet(dashboard)'!$D$27*12,'Input sheet(dashboard)'!$D$3*(1+'Input sheet(dashboard)'!$E$24)^B23,0) -> 9619824.3 | K23: =IF(B23<='Input sheet(dashboard)'!$D$27*12,J23*'Input sheet(dashboard)'!$E$8,0) -> 9963.6946 | L23: =IF(B23<='Input sheet(dashboard)'!$D$27*12,'Input sheet(dashboard)'!$D$9*(1+'Input sheet(dashboard)'!$E$22)^B23,0) -> 3126.0388 | M23: =IF(B23=1,'Input sheet(dashboard)'!$D$3*'Input sheet(dashboard)'!$D$10,0) -> 0 | N23: =IF(B23='Input sheet(dashboard)'!$D$27*12,J23*'Input sheet(dashboard)'!$D$11,0) -> 0 | O23: =IF(SUM(F23:F34)>=150000,150000/12*'Input sheet(dashboard)'!$D$28,SUM(F23:F34)/12*'Input sheet(dashboard)'!$D$28) -> 1875 | P23: =IF(D23=12,IF(SUM(F12:F24)>=150000,150000*0.15,SUM(F12:F24)*0.15),0) -> 0 | Q23: =IF(B23<='Input sheet(dashboard)'!$D$27*12,'Input sheet(dashboard)'!$D$12/12,0) -> 192.5 | R23: =IF(B23<='Input sheet(dashboard)'!$D$27*12,('Input sheet(dashboard)'!$D$15/12)*(1+'Input sheet(dashboard)'!$E$22)^Calculations!B23,0) -> 347.33764 | S23: =IF(B23<='Input sheet(dashboard)'!$D$27*12,(E23+G23+K23+L23-O23+M23+Q23+R23),0) -> 54775.44 | T23: =IF(B23<='Input sheet(dashboard)'!$D$27*12,IF(D23=12,SUM(S12:S23),0),0) -> 0 | U23: =IF(B23<='Input sheet(dashboard)'!$D$27*12,IF(S23<AD23,AD23-S23,0),0) -> 0 | V23: =IF(B23<='Input sheet(dashboard)'!$D$27*12,V22*(1+'Input sheet(dashboard)'!$E$25)+U23,0) -> 0 | W23: =IF(B23<='Input sheet(dashboard)'!$D$27*12,J23-I23+V23-N23,0) -> 1860930.4 | X23: =IF(B23<='Input sheet(dashboard)'!$D$27*12,'Input sheet(dashboard)'!$D$17*(1+'Input sheet(dashboard)'!$E$23)^(B23-1),0) -> 27985.516 | AB23: =IF(B23=1,'Input sheet(dashboard)'!$D$18*Calculations!X23,IF(Calculations!B23=12*'Input sheet(dashboard)'!$D$27,'Input sheet(dashboard)'!$D$18*-Calculations!X23,0)) -> 0 | AC23: =IF(B23<='Input sheet(dashboard)'!$D$27*12,IF(MOD(B22,'Input sheet(dashboard)'!$D$19*12),0,'Input sheet(dashboard)'!$D$20*(1+'Input sheet(dashboard)'!$E$22)^Calculations!B23),0) -> 0 | AD23: =X23+Y23+AB23+AC23 -> 27985.516 | AE23: =IF(B23<='Input sheet(dashboard)'!$D$27*12,IF(D23=12,SUM(AD12:AD23),0),0) -> 0 | AF23: =S23-AD23 -> 26789.924 | AG23: =IF(AF23>0,AF23,0) -> 26789.924 | AH23: =IF(B23<='Input sheet(dashboard)'!$D$27*12,AH22*(1+'Input sheet(dashboard)'!$E$25)+AG23," ") -> 1633013.7
B24: =B23+1 -> 21 | C24: =C12+1 -> 2 | D24: =D12 -> 9 | E24: =IF(C24<='Input sheet(dashboard)'!$D$6, -PMT('Input sheet(dashboard)'!$E$5,'Input sheet(dashboard)'!$D$6*12,'Input sheet(dashboard)'!$D$3*'Input sheet(dashboard)'!$D$4),0) -> 39834.138 | F24: =I23*'Input sheet(dashboard)'!$E$5 -> 28264.01 | G24: =IF(C24<='Input sheet(dashboard)'!$D$6,E24*'Input sheet(dashboard)'!$D$7,0) -> 3186.731 | H24: =E24-F24 -> 11570.128 | I24: =I23-H24 -> 7747323.7 | J24: =IF(B24<='Input sheet(dashboard)'!$D$27*12,'Input sheet(dashboard)'!$D$3*(1+'Input sheet(dashboard)'!$E$24)^B24,0) -> 9659016.6 | K24: =IF(B24<='Input sheet(dashboard)'!$D$27*12,J24*'Input sheet(dashboard)'!$E$8,0) -> 10004.288 | L24: =IF(B24<='Input sheet(dashboard)'!$D$27*12,'Input sheet(dashboard)'!$D$9*(1+'Input sheet(dashboard)'!$E$22)^B24,0) -> 3132.4779 | M24: =IF(B24=1,'Input sheet(dashboard)'!$D$3*'Input sheet(dashboard)'!$D$10,0) -> 0 | N24: =IF(B24='Input sheet(dashboard)'!$D$27*12,J24*'Input sheet(dashboard)'!$D$11,0) -> 0 | O24: =IF(SUM(F24:F35)>=150000,150000/12*'Input sheet(dashboard)'!$D$28,SUM(F24:F35)/12*'Input sheet(dashboard)'!$D$28) -> 1875 | P24: =IF(D24=12,IF(SUM(F13:F25)>=150000,150000*0.15,SUM(F13:F25)*0.15),0) -> 0 | Q24: =IF(B24<='Input sheet(dashboard)'!$D$27*12,'Input sheet(dashboard)'!$D$12/12,0) -> 192.5 | R24: =IF(B24<='Input sheet(dashboard)'!$D$27*12,('Input sheet(dashboard)'!$D$15/12)*(1+'Input sheet(dashboard)'!$E$22)^Calculations!B24,0) -> 348.0531 | S24: =IF(B24<='Input sheet(dashboard)'!$D$27*12,(E24+G24+K24+L24-O24+M24+Q24+R24),0) -> 54823.188 | T24: =IF(B24<='Input sheet(dashboard)'!$D$27*12,IF(D24=12,SUM(S13:S24),0),0) -> 0 | U24: =IF(B24<='Input sheet(dashboard)'!$D$27*12,IF(S24<AD24,AD24-S24,0),0) -> 0 | V24: =IF(B24<='Input sheet(dashboard)'!$D$27*12,V23*(1+'Input sheet(dashboard)'!$E$25)+U24,0) -> 0 | W24: =IF(B24<='Input sheet(dashboard)'!$D$27*12,J24-I24+V24-N24,0) -> 1911692.9 | X24: =IF(B24<='Input sheet(dashboard)'!$D$27*12,'Input sheet(dashboard)'!$D$17*(1+'Input sheet(dashboard)'!$E$23)^(B24-1),0) -> 28099.533 | AB24: =IF(B24=1,'Input sheet(dashboard)'!$D$18*Calculations!X24,IF(Calculations!B24=12*'Input sheet(dashboard)'!$D$27,'Input sheet(dashboard)'!$D$18*-Calculations!X24,0)) -> 0 | AC24: =IF(B24<='Input sheet(dashboard)'!$D$27*12,IF(MOD(B23,'Input sheet(dashboard)'!$D$19*12),0,'Input sheet(dashboard)'!$D$20*(1+'Input sheet(dashboard)'!$E$22)^Calculations!B24),0) -> 0 | AD24: =X24+Y24+AB24+AC24 -> 28099.533 | AE24: =IF(B24<='Input sheet(dashboard)'!$D$27*12,IF(D24=12,SUM(AD13:AD24),0),0) -> 0 | AF24: =S24-AD24 -> 26723.655 | AG24: =IF(AF24>0,AF24,0) -> 26723.655 | AH24: =IF(B24<='Input sheet(dashboard)'!$D$27*12,AH23*(1+'Input sheet(dashboard)'!$E$25)+AG24," ") -> 1670244.2
